<?xml version="1.0"?>

<robot xmlns:xacro="http://ros.org/wiki/xacro">

  <xacro:include filename="$(find talos_description)/urdf/deg_to_rad.xacro" />

  <xacro:macro name="talos_gripper" params="name parent reflect">

            <xacro:macro name="dummy_mimic_joint" params="name parent">
              <link name="${name}_dummy_mimic_link"/>

              <joint name="${name}_joint_mimic" type="fixed">
                <parent link="${parent}" />
                <child link="${name}_dummy_mimic_link" />
              </joint>
            </xacro:macro>

            <xacro:macro name="finger_mimic_dummy" params="name">
              <xacro:dummy_mimic_joint name="${name}_fingertip_1" parent="${name}_base_link"/>
              <xacro:dummy_mimic_joint name="${name}_fingertip_2" parent="${name}_base_link"/>
              <xacro:dummy_mimic_joint name="${name}_inner_single" parent="${name}_base_link"/>
              <xacro:dummy_mimic_joint name="${name}_fingertip_3" parent="${name}_base_link"/>
              <xacro:dummy_mimic_joint name="${name}_motor_single" parent="${name}_base_link"/> 
              <xacro:dummy_mimic_joint name="${name}_inner_double" parent="${name}_base_link"/>                         
            </xacro:macro>

            <link name="${name}_base_link">
              <xacro:call macro="${name}_base_link_inertial" />

              <visual>
                <origin xyz="0 0 0" rpy="0 0 0" />
                <geometry>
                  <mesh filename="package://talos_description/meshes/gripper/base_link.STL" scale="1 1 1"/>
                </geometry>
                <material name="DarkGrey"/>
              </visual>

              <collision>
                <origin xyz="0 0 0" rpy="0 0 0" />
                <geometry>
                  <mesh filename="package://talos_description/meshes/gripper/base_link_collision.STL" scale="1 1 1"/>
                </geometry>
              </collision>
            </link>

            <joint name="${name}_base_link_joint" type="fixed">
              <parent link="${parent}"/>
              <child link="${name}_base_link"/>
              <origin xyz="0.00000 0.00000 -0.02875"
                      rpy="${0.00000 * deg_to_rad} ${0.00000 * deg_to_rad} ${0.00000 * deg_to_rad}"/>
              <axis xyz="0 0 0" />
            </joint>


            <link name="${name}_motor_double_link">
              <xacro:call macro="${name}_motor_double_link_inertial" />

              <visual>
                <origin xyz="0 0 0" rpy="0 0 0" />
                <geometry>
                  <mesh filename="package://talos_description/meshes/gripper/gripper_motor_double.STL" scale="1 1 1"/>
                </geometry>
              <material name="Orange"/>
              </visual>

              <collision>
                <origin xyz="0 0 0" rpy="0 0 0" />
                <geometry>
                  <mesh filename="package://talos_description/meshes/gripper/gripper_motor_double_collision.STL" scale="1 1 1"/>
                </geometry>
              </collision>
            </link>

            <joint name="${name}_joint" type="revolute">
              <parent link="${name}_base_link"/>
              <child link="${name}_motor_double_link"/>
              <origin xyz="0.0 0.02025 -0.03"
                      rpy="${0.0 * deg_to_rad} ${0.0 * deg_to_rad} ${0.0 * deg_to_rad}"/>
              <axis xyz="1 0 0" />
              <limit lower="${-55.0 * deg_to_rad}" upper="${0.0 * deg_to_rad}" effort="1.0" velocity="1.0" />
              <dynamics friction="1.0" damping="1.0"/>
            </joint>


            <link name="${name}_inner_double_link">
              <xacro:call macro="${name}_inner_double_link_inertial" />

              <visual>
                <origin xyz="0 0 0" rpy="0 0 0" />
                <geometry>
                  <mesh filename="package://talos_description/meshes/gripper/inner_double.STL" scale="1 1 1"/>
                </geometry>
              <material name="Orange"/>
              </visual>

              <collision>
                <origin xyz="0 0 0" rpy="0 0 0" />
                <geometry>
                  <mesh filename="package://talos_description/meshes/gripper/inner_double_collision.STL" scale="1 1 1"/>
                </geometry>
              </collision>
            </link>

            <joint name="${name}_inner_double_joint" type="revolute">
              <parent link="${name}_base_link"/>
              <child link="${name}_inner_double_link"/>
              <origin xyz="0.00000 0.00525 -0.05598"
                      rpy="${0.00000 * deg_to_rad} ${0.00000 * deg_to_rad} ${0.00000 * deg_to_rad}"/>
              <axis xyz="1 0 0" />
              <limit lower="${-60.0 * deg_to_rad}" upper="${0.0 * deg_to_rad}" effort="100.0" velocity="1.0" />
              <mimic joint="${name}_joint" multiplier="${1.0}" offset="0.0" />
            </joint>



            <link name="${name}_fingertip_1_link">
              <xacro:call macro="${name}_fingertip_1_link_inertial" />

              <visual>
                <origin xyz="0 0 0" rpy="0 0 0" />
                <geometry>
                  <mesh filename="package://talos_description/meshes/gripper/fingertip.STL" scale="1 1 1"/>
                </geometry>
              <material name="DarkGrey"/>
              </visual>

              <collision>
                <origin xyz="0 0 0" rpy="0 0 0" />
                <geometry>
                  <mesh filename="package://talos_description/meshes/gripper/fingertip_collision.STL" scale="1 1 1"/>
                </geometry>
              </collision>
            </link>


            <joint name="${name}_fingertip_1_joint" type="revolute">
              <parent link="${name}_inner_double_link"/>
              <child link="${name}_fingertip_1_link"/>
              <origin xyz="0.03200 0.04589 -0.06553"
                      rpy="${0.00000 * deg_to_rad} ${0.00000 * deg_to_rad} ${0.00000 * deg_to_rad}"/>
              <axis xyz="1 0 0" />
              <limit lower="${0.0 * deg_to_rad}" upper="${60.0 * deg_to_rad}" effort="100.0" velocity="1.0" />
              <mimic joint="${name}_joint" multiplier="${-1.0}" offset="0.0" />
            </joint>


            <link name="${name}_fingertip_2_link">
              <xacro:call macro="${name}_fingertip_2_link_inertial" />

              <visual>
                <origin xyz="0 0 0" rpy="0 0 0" />
                <geometry>
                  <mesh filename="package://talos_description/meshes/gripper/fingertip.STL" scale="1 1 1"/>
                </geometry>
                <material name="DarkGrey"/>
              </visual>

              <collision>
                <origin xyz="0 0 0" rpy="0 0 0" />
                <geometry>
                  <mesh filename="package://talos_description/meshes/gripper/fingertip_collision.STL" scale="1 1 1"/>
                </geometry>
              </collision>
            </link>

            <joint name="${name}_fingertip_2_joint" type="revolute">
              <parent link="${name}_inner_double_link"/>
              <child link="${name}_fingertip_2_link"/>
              <origin xyz="-0.03200 0.04589 -0.06553"
                      rpy="${0.00000 * deg_to_rad} ${0.00000 * deg_to_rad} ${0.00000 * deg_to_rad}"/>
              <axis xyz="1 0 0" />
              <limit lower="${0.0 * deg_to_rad}" upper="${60.0 * deg_to_rad}" effort="100.0" velocity="1.0" />
              <mimic joint="${name}_joint" multiplier="${-1.0}" offset="0.0" />
            </joint>


            <link name="${name}_motor_single_link">
              <xacro:call macro="${name}_motor_single_link_inertial" />

              <visual>
                <origin xyz="0 0 0" rpy="0 0 0" />
                <geometry>
                  <mesh filename="package://talos_description/meshes/gripper/gripper_motor_single.STL" scale="1 1 1"/>
                </geometry>
              <material name="Orange"/>
              </visual>

              <collision>
                <origin xyz="0 0 0" rpy="0 0 0" />
                <geometry>
                  <mesh filename="package://talos_description/meshes/gripper/gripper_motor_single_collision.STL" scale="1 1 1"/>
                </geometry>
              </collision>
            </link>

            <joint name="${name}_motor_single_joint" type="revolute">
              <parent link="${name}_base_link"/>
              <child link="${name}_motor_single_link"/>
              <origin xyz="0.00000 -0.02025 -0.03000"
                      rpy="${0.00000 * deg_to_rad} ${0.00000 * deg_to_rad} ${0.00000 * deg_to_rad}"/>
              <axis xyz="1 0 0" />
              <limit lower="${0.0 * deg_to_rad}" upper="${60.0 * deg_to_rad}" effort="100.0" velocity="1.0" />
              <mimic joint="${name}_joint" multiplier="${-1.0}" offset="0.0" />
            </joint>



            <link name="${name}_inner_single_link">
              <xacro:call macro="${name}_inner_single_link_inertial" />

              <visual>
                <origin xyz="0 0 0" rpy="0 0 0" />
                <geometry>
                  <mesh filename="package://talos_description/meshes/gripper/inner_single.STL" scale="1 1 1"/>
                </geometry>
              <material name="Orange"/>
              </visual>

              <collision>
                <origin xyz="0 0 0" rpy="0 0 0" />
                <geometry>
                  <mesh filename="package://talos_description/meshes/gripper/inner_single_collision.STL" scale="1 1 1"/>
                </geometry>
              </collision>
            </link>

            <joint name="${name}_inner_single_joint" type="revolute">
              <parent link="${name}_base_link"/>
              <child link="${name}_inner_single_link"/>
              <origin xyz="0.00000 -0.00525 -0.05598"
                      rpy="${0.00000 * deg_to_rad} ${0.00000 * deg_to_rad} ${0.00000 * deg_to_rad}"/>
              <axis xyz="1 0 0" />
              <limit lower="${0.0 * deg_to_rad}" upper="${60.0 * deg_to_rad}" effort="100.0" velocity="1.0" />
              <mimic joint="${name}_joint" multiplier="${-1.0}" offset="0.0" />
            </joint>


            <link name="${name}_fingertip_3_link">
              <xacro:call macro="${name}_fingertip_3_link_inertial" />

              <visual>
                <origin xyz="0 0 0" rpy="0 0 0" />
                <geometry>
                  <mesh filename="package://talos_description/meshes/gripper/fingertip.STL" scale="1 1 1"/>
                </geometry>
              <material name="DarkGrey"/>
              </visual>

              <collision>
                <origin xyz="0 0 0" rpy="0 0 0" />
                <geometry>
                  <mesh filename="package://talos_description/meshes/gripper/fingertip_collision.STL" scale="1 1 1"/>
                </geometry>
              </collision>
            </link>

            <joint name="${name}_fingertip_3_joint" type="revolute">
              <parent link="${name}_inner_single_link"/>
              <child link="${name}_fingertip_3_link"/>
              <origin xyz="0.00000 -0.04589 -0.06553"
                      rpy="${0.00000 * deg_to_rad} ${0.00000 * deg_to_rad} ${180.00000 * deg_to_rad}"/>
              <axis xyz="1 0 0" />
              <limit lower="${0.0 * deg_to_rad}" upper="${60.0 * deg_to_rad}" effort="100.0" velocity="1.0" />
              <mimic joint="${name}_joint" multiplier="${-1.0}" offset="0.0" />
            </joint>


            <gazebo reference="${name}_joint">
                <implicitSpringDamper>1</implicitSpringDamper>
                <provideFeedback>1</provideFeedback>
              </gazebo>

              <gazebo reference="${name}_inner_double_joint">
                <implicitSpringDamper>1</implicitSpringDamper>
                <provideFeedback>1</provideFeedback>
              </gazebo>

              <gazebo reference="${name}_fingertip_1_joint">
                <implicitSpringDamper>1</implicitSpringDamper>
                <provideFeedback>1</provideFeedback>
              </gazebo>

              <gazebo reference="${name}_fingertip_2_joint">
                <implicitSpringDamper>1</implicitSpringDamper>
                <provideFeedback>1</provideFeedback>
              </gazebo>

              <gazebo reference="${name}_motor_single_joint">
                <implicitSpringDamper>1</implicitSpringDamper>
                <provideFeedback>1</provideFeedback>
              </gazebo>

              <gazebo reference="${name}_fingertip_3_joint">
                <implicitSpringDamper>1</implicitSpringDamper>
                <provideFeedback>1</provideFeedback>
              </gazebo>

              <gazebo reference="${name}_base_link">
                <material>Gazebo/FlatBlack</material>
              </gazebo>

              <gazebo reference="${name}_motor_double_link">
                <material>Gazebo/Orange</material>
              </gazebo>

              <gazebo reference="${name}_inner_double_link">
                <material>Gazebo/Orange</material>
              </gazebo>

              <gazebo reference="${name}_fingertip_1_link">
                <material>Gazebo/FlatBlack</material>
              </gazebo>

              <gazebo reference="${name}_motor_single_link">
                <material>Gazebo/Orange</material>
              </gazebo>


              <gazebo reference="${name}_inner_single_link">
                <material>Gazebo/Orange</material>
              </gazebo>

              <gazebo reference="${name}_fingertip_2_link">
                <material>Gazebo/FlatBlack</material>
              </gazebo>

              <gazebo reference="${name}_fingertip_3_link">
                <material>Gazebo/FlatBlack</material>
              </gazebo>

              <!-- Temporary fix until mimic joint works properly with MoveIt!-->
              <xacro:finger_mimic_dummy name="${name}"/>
              <xacro:dummy_mimic_joint name="${name}_link" parent="${name}_base_link"/>

  </xacro:macro>
</robot>
